{
 "cells": [
  {
   "cell_type": "code",
   "execution_count": 4,
   "metadata": {
    "collapsed": true
   },
   "outputs": [],
   "source": [
    "from hdfs import *"
   ]
  },
  {
   "cell_type": "code",
   "execution_count": 26,
   "metadata": {},
   "outputs": [
    {
     "data": {
      "text/plain": [
       "<Client(url='http://192.168.0.96:50070')>"
      ]
     },
     "execution_count": 26,
     "metadata": {},
     "output_type": "execute_result"
    }
   ],
   "source": [
    "client=Client('http://192.168.0.96:50070')\n",
    "client"
   ]
  },
  {
   "cell_type": "code",
   "execution_count": 36,
   "metadata": {},
   "outputs": [
    {
     "data": {
      "text/plain": [
       "u'file1.txt'"
      ]
     },
     "execution_count": 36,
     "metadata": {},
     "output_type": "execute_result"
    }
   ],
   "source": [
    "p = client.list('/user/root/input/')[0]\n",
    "p"
   ]
  },
  {
   "cell_type": "code",
   "execution_count": 37,
   "metadata": {},
   "outputs": [
    {
     "ename": "ConnectionError",
     "evalue": "HTTPConnectionPool(host='hadoop-slave1', port=50075): Max retries exceeded with url: /webhdfs/v1/user/root/input/file1.txt?op=OPEN&namenoderpcaddress=hadoop-master:9000&offset=0 (Caused by NewConnectionError('<requests.packages.urllib3.connection.HTTPConnection object at 0x10bcae210>: Failed to establish a new connection: [Errno 8] nodename nor servname provided, or not known',))",
     "output_type": "error",
     "traceback": [
      "\u001b[0;31m---------------------------------------------------------------------------\u001b[0m",
      "\u001b[0;31mConnectionError\u001b[0m                           Traceback (most recent call last)",
      "\u001b[0;32m<ipython-input-37-e14c9aaadd71>\u001b[0m in \u001b[0;36m<module>\u001b[0;34m()\u001b[0m\n\u001b[0;32m----> 1\u001b[0;31m \u001b[0;32mwith\u001b[0m \u001b[0mclient\u001b[0m\u001b[0;34m.\u001b[0m\u001b[0mread\u001b[0m\u001b[0;34m(\u001b[0m\u001b[0;34m'/user/root/input/file1.txt'\u001b[0m\u001b[0;34m)\u001b[0m \u001b[0;32mas\u001b[0m \u001b[0mfs\u001b[0m\u001b[0;34m:\u001b[0m\u001b[0;34m\u001b[0m\u001b[0m\n\u001b[0m\u001b[1;32m      2\u001b[0m     \u001b[0mcontent\u001b[0m \u001b[0;34m=\u001b[0m \u001b[0mfs\u001b[0m\u001b[0;34m.\u001b[0m\u001b[0mread\u001b[0m\u001b[0;34m(\u001b[0m\u001b[0;34m)\u001b[0m\u001b[0;34m\u001b[0m\u001b[0m\n\u001b[1;32m      3\u001b[0m     \u001b[0;32mprint\u001b[0m\u001b[0;34m(\u001b[0m\u001b[0mcontent\u001b[0m\u001b[0;34m)\u001b[0m\u001b[0;34m\u001b[0m\u001b[0m\n",
      "\u001b[0;32m/Users/apple/.pyenv/versions/2.7.12/lib/python2.7/contextlib.pyc\u001b[0m in \u001b[0;36m__enter__\u001b[0;34m(self)\u001b[0m\n\u001b[1;32m     15\u001b[0m     \u001b[0;32mdef\u001b[0m \u001b[0m__enter__\u001b[0m\u001b[0;34m(\u001b[0m\u001b[0mself\u001b[0m\u001b[0;34m)\u001b[0m\u001b[0;34m:\u001b[0m\u001b[0;34m\u001b[0m\u001b[0m\n\u001b[1;32m     16\u001b[0m         \u001b[0;32mtry\u001b[0m\u001b[0;34m:\u001b[0m\u001b[0;34m\u001b[0m\u001b[0m\n\u001b[0;32m---> 17\u001b[0;31m             \u001b[0;32mreturn\u001b[0m \u001b[0mself\u001b[0m\u001b[0;34m.\u001b[0m\u001b[0mgen\u001b[0m\u001b[0;34m.\u001b[0m\u001b[0mnext\u001b[0m\u001b[0;34m(\u001b[0m\u001b[0;34m)\u001b[0m\u001b[0;34m\u001b[0m\u001b[0m\n\u001b[0m\u001b[1;32m     18\u001b[0m         \u001b[0;32mexcept\u001b[0m \u001b[0mStopIteration\u001b[0m\u001b[0;34m:\u001b[0m\u001b[0;34m\u001b[0m\u001b[0m\n\u001b[1;32m     19\u001b[0m             \u001b[0;32mraise\u001b[0m \u001b[0mRuntimeError\u001b[0m\u001b[0;34m(\u001b[0m\u001b[0;34m\"generator didn't yield\"\u001b[0m\u001b[0;34m)\u001b[0m\u001b[0;34m\u001b[0m\u001b[0m\n",
      "\u001b[0;32m/Users/apple/.pyenv/versions/2.7.12/lib/python2.7/site-packages/hdfs/client.pyc\u001b[0m in \u001b[0;36mread\u001b[0;34m(self, hdfs_path, offset, length, buffer_size, encoding, chunk_size, delimiter, progress)\u001b[0m\n\u001b[1;32m    676\u001b[0m       \u001b[0moffset\u001b[0m\u001b[0;34m=\u001b[0m\u001b[0moffset\u001b[0m\u001b[0;34m,\u001b[0m\u001b[0;34m\u001b[0m\u001b[0m\n\u001b[1;32m    677\u001b[0m       \u001b[0mlength\u001b[0m\u001b[0;34m=\u001b[0m\u001b[0mlength\u001b[0m\u001b[0;34m,\u001b[0m\u001b[0;34m\u001b[0m\u001b[0m\n\u001b[0;32m--> 678\u001b[0;31m       \u001b[0mbuffersize\u001b[0m\u001b[0;34m=\u001b[0m\u001b[0mbuffer_size\u001b[0m\u001b[0;34m,\u001b[0m\u001b[0;34m\u001b[0m\u001b[0m\n\u001b[0m\u001b[1;32m    679\u001b[0m     )\n\u001b[1;32m    680\u001b[0m     \u001b[0;32mtry\u001b[0m\u001b[0;34m:\u001b[0m\u001b[0;34m\u001b[0m\u001b[0m\n",
      "\u001b[0;32m/Users/apple/.pyenv/versions/2.7.12/lib/python2.7/site-packages/hdfs/client.pyc\u001b[0m in \u001b[0;36mapi_handler\u001b[0;34m(client, hdfs_path, data, strict, **params)\u001b[0m\n\u001b[1;32m    116\u001b[0m             \u001b[0;32mif\u001b[0m \u001b[0mlen\u001b[0m\u001b[0;34m(\u001b[0m\u001b[0mclient\u001b[0m\u001b[0;34m.\u001b[0m\u001b[0m_urls\u001b[0m\u001b[0;34m)\u001b[0m \u001b[0;34m>\u001b[0m \u001b[0;36m1\u001b[0m\u001b[0;34m:\u001b[0m\u001b[0;34m\u001b[0m\u001b[0m\n\u001b[1;32m    117\u001b[0m               \u001b[0m_logger\u001b[0m\u001b[0;34m.\u001b[0m\u001b[0mwarning\u001b[0m\u001b[0;34m(\u001b[0m\u001b[0;34m'No reachable host, raising last error.'\u001b[0m\u001b[0;34m)\u001b[0m\u001b[0;34m\u001b[0m\u001b[0m\n\u001b[0;32m--> 118\u001b[0;31m             \u001b[0;32mraise\u001b[0m \u001b[0merr\u001b[0m\u001b[0;34m\u001b[0m\u001b[0m\n\u001b[0m\u001b[1;32m    119\u001b[0m \u001b[0;34m\u001b[0m\u001b[0m\n\u001b[1;32m    120\u001b[0m     \u001b[0mapi_handler\u001b[0m\u001b[0;34m.\u001b[0m\u001b[0m__name__\u001b[0m \u001b[0;34m=\u001b[0m \u001b[0;34m'%s_handler'\u001b[0m \u001b[0;34m%\u001b[0m \u001b[0;34m(\u001b[0m\u001b[0moperation\u001b[0m\u001b[0;34m.\u001b[0m\u001b[0mlower\u001b[0m\u001b[0;34m(\u001b[0m\u001b[0;34m)\u001b[0m\u001b[0;34m,\u001b[0m \u001b[0;34m)\u001b[0m\u001b[0;34m\u001b[0m\u001b[0m\n",
      "\u001b[0;31mConnectionError\u001b[0m: HTTPConnectionPool(host='hadoop-slave1', port=50075): Max retries exceeded with url: /webhdfs/v1/user/root/input/file1.txt?op=OPEN&namenoderpcaddress=hadoop-master:9000&offset=0 (Caused by NewConnectionError('<requests.packages.urllib3.connection.HTTPConnection object at 0x10bcae210>: Failed to establish a new connection: [Errno 8] nodename nor servname provided, or not known',))"
     ]
    }
   ],
   "source": [
    "with client.read('/user/root/input/file1.txt') as fs:\n",
    "    content = fs.read()\n",
    "    print(content)"
   ]
  },
  {
   "cell_type": "code",
   "execution_count": null,
   "metadata": {
    "collapsed": true
   },
   "outputs": [],
   "source": []
  }
 ],
 "metadata": {
  "kernelspec": {
   "display_name": "Python 2",
   "language": "python",
   "name": "python2"
  },
  "language_info": {
   "codemirror_mode": {
    "name": "ipython",
    "version": 2
   },
   "file_extension": ".py",
   "mimetype": "text/x-python",
   "name": "python",
   "nbconvert_exporter": "python",
   "pygments_lexer": "ipython2",
   "version": "2.7.12"
  }
 },
 "nbformat": 4,
 "nbformat_minor": 2
}
